Workbook

Sheet NeetCode 150
A1: # | B1: Topic | C1: Problem | D1: Difficulty | E1: LeetCode Link | F1: Status | G1: Notes
A2: 1 | B2: Arrays & Hashing | C2: Contains Duplicate | D2: Easy | E2: https://leetcode.com/problems/contains-duplicate/
A3: 2 | B3: Arrays & Hashing | C3: Valid Anagram | D3: Easy | E3: https://leetcode.com/problems/valid-anagram/
A4: 3 | B4: Arrays & Hashing | C4: Two Sum | D4: Easy | E4: https://leetcode.com/problems/two-sum/
A5: 4 | B5: Arrays & Hashing | C5: Group Anagrams | D5: Medium | E5: https://leetcode.com/problems/group-anagrams/
A6: 5 | B6: Arrays & Hashing | C6: Top K Frequent Elements | D6: Medium | E6: https://leetcode.com/problems/top-k-frequent-elements/
A7: 6 | B7: Arrays & Hashing | C7: Encode and Decode Strings | D7: Medium | E7: https://leetcode.com/problems/encode-and-decode-strings/
A8: 7 | B8: Arrays & Hashing | C8: Product of Array Except Self | D8: Medium | E8: https://leetcode.com/problems/product-of-array-except-self/
A9: 8 | B9: Arrays & Hashing | C9: Valid Sudoku | D9: Medium | E9: https://leetcode.com/problems/valid-sudoku/
A10: 9 | B10: Arrays & Hashing | C10: Longest Consecutive Sequence | D10: Medium | E10: https://leetcode.com/problems/longest-consecutive-sequence/
A11: 10 | B11: Two Pointers | C11: Valid Palindrome | D11: Easy | E11: https://leetcode.com/problems/valid-palindrome/
A12: 11 | B12: Two Pointers | C12: Two Sum II - Input Array Is Sorted | D12: Medium | E12: https://leetcode.com/problems/two-sum-ii-input-array-is-sorted/
A13: 12 | B13: Two Pointers | C13: 3Sum | D13: Medium | E13: https://leetcode.com/problems/3sum/
... A151: 150 | B151: Bit Manipulation | C151: Reverse Integer | D151: Medium | E151: https://leetcode.com/problems/reverse-integer/

Sheet Patterns (30 Topics)
A1: # | B1: Pattern / Topic | C1: LC # | D1: Problem | E1: Difficulty | F1: LeetCode Link | G1: Status
A2: 1. Sliding Window
A3: 1 | B3: Sliding Window | C3: 3 | D3: Longest Substring Without Repeating Characters | E3: Medium | F3: https://leetcode.com/problems/longest-substring-without-repeating-characters/
A4: 1 | B4: Sliding Window | C4: 76 | D4: Minimum Window Substring | E4: Hard | F4: https://leetcode.com/problems/minimum-window-substring/
A5: 1 | B5: Sliding Window | C5: 209 | D5: Minimum Size Subarray Sum | E5: Medium | F5: https://leetcode.com/problems/minimum-size-subarray-sum/
A6: 1 | B6: Sliding Window | C6: 424 | D6: Longest Repeating Character Replacement | E6: Medium | F6: https://leetcode.com/problems/longest-repeating-character-replacement/
A7: 1 | B7: Sliding Window | C7: 567 | D7: Permutation in String | E7: Medium | F7: https://leetcode.com/problems/permutation-in-string/
A8: 1 | B8: Sliding Window | C8: 904 | D8: Fruit Into Baskets | E8: Medium | F8: https://leetcode.com/problems/fruit-into-baskets/
A9: 2. Two Pointers
A10: 2 | B10: Two Pointers | C10: 11 | D10: Container With Most Water | E10: Medium | F10: https://leetcode.com/problems/container-with-most-water/
A11: 2 | B11: Two Pointers | C11: 15 | D11: 3Sum | E11: Medium | F11: https://leetcode.com/problems/3sum/
A12: 2 | B12: Two Pointers | C12: 16 | D12: 3Sum Closest | E12: Medium | F12: https://leetcode.com/problems/3sum-closest/
A13: 2 | B13: Two Pointers | C13: 18 | D13: 4Sum | E13: Medium | F13: https://leetcode.com/problems/4sum/
A14: 2 | B14: Two Pointers | C14: 42 | D14: Trapping Rain Water | E14: Hard | F14: https://leetcode.com/problems/trapping-rain-water/
A15: 2 | B15: Two Pointers | C15: 167 | D15: Two Sum II - Input Array Is Sorted | E15: Medium | F15: https://leetcode.com/problems/two-sum-ii-input-array-is-sorted/
A16: 3. Fast/Slow Pointers (Linked List)
A17: 3 | B17: Fast/Slow Pointers (Linked List) | C17: 141 | D17: Linked List Cycle | E17: Easy | F17: https://leetcode.com/problems/linked-list-cycle/
A18: 3 | B18: Fast/Slow Pointers (Linked List) | C18: 142 | D18: Linked List Cycle II | E18: Medium | F18: https://leetcode.com/problems/linked-list-cycle-ii/
A19: 3 | B19: Fast/Slow Pointers (Linked List) | C19: 19 | D19: Remove Nth Node From End of List | E19: Medium | F19: https://leetcode.com/problems/remove-nth-node-from-end-of-list/
A20: 3 | B20: Fast/Slow Pointers (Linked List) | C20: 876 | D20: Middle of the Linked List | E20: Easy | F20: https://leetcode.com/problems/middle-of-the-linked-list/
A21: 3 | B21: Fast/Slow Pointers (Linked List) | C21: 160 | D21: Intersection of Two Linked Lists | E21: Easy | F21: https://leetcode.com/problems/intersection-of-two-linked-lists/
A22: 3 | B22: Fast/Slow Pointers (Linked List) | C22: 234 | D22: Palindrome Linked List | E22: Easy | F22: https://leetcode.com/problems/palindrome-linked-list/
A23: 4. Binary Search on Sorted Data
A24: 4 | B24: Binary Search on Sorted Data | C24: 33 | D24: Search in Rotated Sorted Array | E24: Medium | F24: https://leetcode.com/problems/search-in-rotated-sorted-array/
A25: 4 | B25: Binary Search on Sorted Data | C25: 34 | D25: Find First and Last Position of Element in Sorted Array | E25: Medium | F25: https://leetcode.com/problems/find-first-and-last-position-of-element-in-sorted-array/
A26: 4 | B26: Binary Search on Sorted Data | C26: 35 | D26: Search Insert Position | E26: Easy | F26: https://leetcode.com/problems/search-insert-position/
A27: 4 | B27: Binary Search on Sorted Data | C27: 153 | D27: Find Minimum in Rotated Sorted Array | E27: Medium | F27: https://leetcode.com/problems/find-minimum-in-rotated-sorted-array/
A28: 4 | B28: Binary Search on Sorted Data | C28: 162 | D28: Find Peak Element | E28: Medium | F28: https://leetcode.com/problems/find-peak-element/
A29: 4 | B29: Binary Search on Sorted Data | C29: 704 | D29: Binary Search | E29: Easy | F29: https://leetcode.com/problems/binary-search/
A30: 5. Binary Search on Answer
A31: 5 | B31: Binary Search on Answer | C31: 875 | D31: Koko Eating Bananas | E31: Medium | F31: https://leetcode.com/problems/koko-eating-bananas/
A32: 5 | B32: Binary Search on Answer | C32: 1011 | D32: Capacity To Ship Packages Within D Days | E32: Medium | F32: https://leetcode.com/problems/capacity-to-ship-packages-within-d-days/
A33: 5 | B33: Binary Search on Answer | C33: 410 | D33: Split Array Largest Sum | E33: Hard | F33: https://leetcode.com/problems/split-array-largest-sum/
A34: 5 | B34: Binary Search on Answer | C34: 774 | D34: Minimize Max Distance to Gas Station | E34: Hard | F34: https://leetcode.com/problems/minimize-max-distance-to-gas-station/
A35: 5 | B35: Binary Search on Answer | C35: 1283 | D35: Find the Smallest Divisor Given a Threshold | E35: Medium | F35: https://leetcode.com/problems/find-the-smallest-divisor-given-a-threshold/
A36: 5 | B36: Binary Search on Answer | C36: 1482 | D36: Minimum Number of Days to Make m Bouquets | E36: Medium | F36: https://leetcode.com/problems/minimum-number-of-days-to-make-m-bouquets/
A37: 6. Hashing / Frequency Maps
A38: 6 | B38: Hashing / Frequency Maps | C38: 1 | D38: Two Sum | E38: Easy | F38: https://leetcode.com/problems/two-sum/
A39: 6 | B39: Hashing / Frequency Maps | C39: 49 | D39: Group Anagrams | E39: Medium | F39: https://leetcode.com/problems/group-anagrams/
A40: 6 | B40: Hashing / Frequency Maps | C40: 128 | D40: Longest Consecutive Sequence | E40: Medium | F40: https://leetcode.com/problems/longest-consecutive-sequence/
...

Sheet Summary
A1: NeetCode 150 — Topic Summary
A3: Topic | B3: Easy | C3: Medium | D3: Hard | E3: Total | F3: Done | G3: Progress
A4: Arrays & Hashing | B4: =COUNTIFS('NeetCode 150'!B2:B151,A4,'NeetCode 150'!D2:D151,"Easy") -> 3 | C4: =COUNTIFS('NeetCode 150'!B2:B151,A4,'NeetCode 150'!D2:D151,"Medium") -> 6 | D4: =COUNTIFS('NeetCode 150'!B2:B151,A4,'NeetCode 150'!D2:D151,"Hard") -> 0 | E4: =SUM(B4:D4) -> 9 | F4: =COUNTIFS('NeetCode 150'!B2:B151,A4,'NeetCode 150'!F2:F151,"Done") -> 0 | G4: =IF(E4=0,0,F4/E4) -> 0
A5: Two Pointers | B5: =COUNTIFS('NeetCode 150'!B2:B151,A5,'NeetCode 150'!D2:D151,"Easy") -> 1 | C5: =COUNTIFS('NeetCode 150'!B2:B151,A5,'NeetCode 150'!D2:D151,"Medium") -> 3 | D5: =COUNTIFS('NeetCode 150'!B2:B151,A5,'NeetCode 150'!D2:D151,"Hard") -> 1 | E5: =SUM(B5:D5) -> 5 | F5: =COUNTIFS('NeetCode 150'!B2:B151,A5,'NeetCode 150'!F2:F151,"Done") -> 0 | G5: =IF(E5=0,0,F5/E5) -> 0
A6: Sliding Window | B6: =COUNTIFS('NeetCode 150'!B2:B151,A6,'NeetCode 150'!D2:D151,"Easy") -> 1 | C6: =COUNTIFS('NeetCode 150'!B2:B151,A6,'NeetCode 150'!D2:D151,"Medium") -> 3 | D6: =COUNTIFS('NeetCode 150'!B2:B151,A6,'NeetCode 150'!D2:D151,"Hard") -> 2 | E6: =SUM(B6:D6) -> 6 | F6: =COUNTIFS('NeetCode 150'!B2:B151,A6,'NeetCode 150'!F2:F151,"Done") -> 0 | G6: =IF(E6=0,0,F6/E6) -> 0
A7: Stack | B7: =COUNTIFS('NeetCode 150'!B2:B151,A7,'NeetCode 150'!D2:D151,"Easy") -> 1 | C7: =COUNTIFS('NeetCode 150'!B2:B151,A7,'NeetCode 150'!D2:D151,"Medium") -> 5 | D7: =COUNTIFS('NeetCode 150'!B2:B151,A7,'NeetCode 150'!D2:D151,"Hard") -> 1 | E7: =SUM(B7:D7) -> 7 | F7: =COUNTIFS('NeetCode 150'!B2:B151,A7,'NeetCode 150'!F2:F151,"Done") -> 0 | G7: =IF(E7=0,0,F7/E7) -> 0
A8: Binary Search | B8: =COUNTIFS('NeetCode 150'!B2:B151,A8,'NeetCode 150'!D2:D151,"Easy") -> 1 | C8: =COUNTIFS('NeetCode 150'!B2:B151,A8,'NeetCode 150'!D2:D151,"Medium") -> 5 | D8: =COUNTIFS('NeetCode 150'!B2:B151,A8,'NeetCode 150'!D2:D151,"Hard") -> 1 | E8: =SUM(B8:D8) -> 7 | F8: =COUNTIFS('NeetCode 150'!B2:B151,A8,'NeetCode 150'!F2:F151,"Done") -> 0 | G8: =IF(E8=0,0,F8/E8) -> 0
A9: Linked List | B9: =COUNTIFS('NeetCode 150'!B2:B151,A9,'NeetCode 150'!D2:D151,"Easy") -> 3 | C9: =COUNTIFS('NeetCode 150'!B2:B151,A9,'NeetCode 150'!D2:D151,"Medium") -> 6 | D9: =COUNTIFS('NeetCode 150'!B2:B151,A9,'NeetCode 150'!D2:D151,"Hard") -> 2 | E9: =SUM(B9:D9) -> 11 | F9: =COUNTIFS('NeetCode 150'!B2:B151,A9,'NeetCode 150'!F2:F151,"Done") -> 0 | G9: =IF(E9=0,0,F9/E9) -> 0
A10: Trees | B10: =COUNTIFS('NeetCode 150'!B2:B151,A10,'NeetCode 150'!D2:D151,"Easy") -> 6 | C10: =COUNTIFS('NeetCode 150'!B2:B151,A10,'NeetCode 150'!D2:D151,"Medium") -> 7 | D10: =COUNTIFS('NeetCode 150'!B2:B151,A10,'NeetCode 150'!D2:D151,"Hard") -> 2 | E10: =SUM(B10:D10) -> 15 | F10: =COUNTIFS('NeetCode 150'!B2:B151,A10,'NeetCode 150'!F2:F151,"Done") -> 0 | G10: =IF(E10=0,0,F10/E10) -> 0
A11: Tries | B11: =COUNTIFS('NeetCode 150'!B2:B151,A11,'NeetCode 150'!D2:D151,"Easy") -> 0 | C11: =COUNTIFS('NeetCode 150'!B2:B151,A11,'NeetCode 150'!D2:D151,"Medium") -> 2 | D11: =COUNTIFS('NeetCode 150'!B2:B151,A11,'NeetCode 150'!D2:D151,"Hard") -> 1 | E11: =SUM(B11:D11) -> 3 | F11: =COUNTIFS('NeetCode 150'!B2:B151,A11,'NeetCode 150'!F2:F151,"Done") -> 0 | G11: =IF(E11=0,0,F11/E11) -> 0
A12: Heap / Priority Queue | B12: =COUNTIFS('NeetCode 150'!B2:B151,A12,'NeetCode 150'!D2:D151,"Easy") -> 2 | C12: =COUNTIFS('NeetCode 150'!B2:B151,A12,'NeetCode 150'!D2:D151,"Medium") -> 4 | D12: =COUNTIFS('NeetCode 150'!B2:B151,A12,'NeetCode 150'!D2:D151,"Hard") -> 1 | E12: =SUM(B12:D12) -> 7 | F12: =COUNTIFS('NeetCode 150'!B2:B151,A12,'NeetCode 150'!F2:F151,"Done") -> 0 | G12: =IF(E12=0,0,F12/E12) -> 0
A13: Backtracking | B13: =COUNTIFS('NeetCode 150'!B2:B151,A13,'NeetCode 150'!D2:D151,"Easy") -> 0 | C13: =COUNTIFS('NeetCode 150'!B2:B151,A13,'NeetCode 150'!D2:D151,"Medium") -> 8 | D13: =COUNTIFS('NeetCode 150'!B2:B151,A13,'NeetCode 150'!D2:D151,"Hard") -> 1 | E13: =SUM(B13:D13) -> 9 | F13: =COUNTIFS('NeetCode 150'!B2:B151,A13,'NeetCode 150'!F2:F151,"Done") -> 0 | G13: =IF(E13=0,0,F13/E13) -> 0
A14: Graphs | B14: =COUNTIFS('NeetCode 150'!B2:B151,A14,'NeetCode 150'!D2:D151,"Easy") -> 0 | C14: =COUNTIFS('NeetCode 150'!B2:B151,A14,'NeetCode 150'!D2:D151,"Medium") -> 12 | D14: =COUNTIFS('NeetCode 150'!B2:B151,A14,'NeetCode 150'!D2:D151,"Hard") -> 1 | E14: =SUM(B14:D14) -> 13 | F14: =COUNTIFS('NeetCode 150'!B2:B151,A14,'NeetCode 150'!F2:F151,"Done") -> 0 | G14: =IF(E14=0,0,F14/E14) -> 0
A15: Advanced Graphs | B15: =COUNTIFS('NeetCode 150'!B2:B151,A15,'NeetCode 150'!D2:D151,"Easy") -> 0 | C15: =COUNTIFS('NeetCode 150'!B2:B151,A15,'NeetCode 150'!D2:D151,"Medium") -> 3 | D15: =COUNTIFS('NeetCode 150'!B2:B151,A15,'NeetCode 150'!D2:D151,"Hard") -> 3 | E15: =SUM(B15:D15) -> 6 | F15: =COUNTIFS('NeetCode 150'!B2:B151,A15,'NeetCode 150'!F2:F151,"Done") -> 0 | G15: =IF(E15=0,0,F15/E15) -> 0
A16: 1-D Dynamic Programming | B16: =COUNTIFS('NeetCode 150'!B2:B151,A16,'NeetCode 150'!D2:D151,"Easy") -> 2 | C16: =COUNTIFS('NeetCode 150'!B2:B151,A16,'NeetCode 150'!D2:D151,"Medium") -> 10 | D16: =COUNTIFS('NeetCode 150'!B2:B151,A16,'NeetCode 150'!D2:D151,"Hard") -> 0 | E16: =SUM(B16:D16) -> 12 | F16: =COUNTIFS('NeetCode 150'!B2:B151,A16,'NeetCode 150'!F2:F151,"Done") -> 0 | G16: =IF(E16=0,0,F16/E16) -> 0
A17: 2-D Dynamic Programming | B17: =COUNTIFS('NeetCode 150'!B2:B151,A17,'NeetCode 150'!D2:D151,"Easy") -> 0 | C17: =COUNTIFS('NeetCode 150'!B2:B151,A17,'NeetCode 150'!D2:D151,"Medium") -> 7 | D17: =COUNTIFS('NeetCode 150'!B2:B151,A17,'NeetCode 150'!D2:D151,"Hard") -> 4 | E17: =SUM(B17:D17) -> 11 | F17: =COUNTIFS('NeetCode 150'!B2:B151,A17,'NeetCode 150'!F2:F151,"Done") -> 0 | G17: =IF(E17=0,0,F17/E17) -> 0
A18: Greedy | B18: =COUNTIFS('NeetCode 150'!B2:B151,A18,'NeetCode 150'!D2:D151,"Easy") -> 0 | C18: =COUNTIFS('NeetCode 150'!B2:B151,A18,'NeetCode 150'!D2:D151,"Medium") -> 8 | D18: =COUNTIFS('NeetCode 150'!B2:B151,A18,'NeetCode 150'!D2:D151,"Hard") -> 0 | E18: =SUM(B18:D18) -> 8 | F18: =COUNTIFS('NeetCode 150'!B2:B151,A18,'NeetCode 150'!F2:F151,"Done") -> 0 | G18: =IF(E18=0,0,F18/E18) -> 0
A19: Intervals | B19: =COUNTIFS('NeetCode 150'!B2:B151,A19,'NeetCode 150'!D2:D151,"Easy") -> 1 | C19: =COUNTIFS('NeetCode 150'!B2:B151,A19,'NeetCode 150'!D2:D151,"Medium") -> 4 | D19: =COUNTIFS('NeetCode 150'!B2:B151,A19,'NeetCode 150'!D2:D151,"Hard") -> 1 | E19: =SUM(B19:D19) -> 6 | F19: =COUNTIFS('NeetCode 150'!B2:B151,A19,'NeetCode 150'!F2:F151,"Done") -> 0 | G19: =IF(E19=0,0,F19/E19) -> 0
A20: Math & Geometry | B20: =COUNTIFS('NeetCode 150'!B2:B151,A20,'NeetCode 150'!D2:D151,"Easy") -> 2 | C20: =COUNTIFS('NeetCode 150'!B2:B151,A20,'NeetCode 150'!D2:D151,"Medium") -> 6 | D20: =COUNTIFS('NeetCode 150'!B2:B151,A20,'NeetCode 150'!D2:D151,"Hard") -> 0 | E20: =SUM(B20:D20) -> 8 | F20: =COUNTIFS('NeetCode 150'!B2:B151,A20,'NeetCode 150'!F2:F151,"Done") -> 0 | G20: =IF(E20=0,0,F20/E20) -> 0
A21: Bit Manipulation | B21: =COUNTIFS('NeetCode 150'!B2:B151,A21,'NeetCode 150'!D2:D151,"Easy") -> 5 | C21: =COUNTIFS('NeetCode 150'!B2:B151,A21,'NeetCode 150'!D2:D151,"Medium") -> 2 | D21: =COUNTIFS('NeetCode 150'!B2:B151,A21,'NeetCode 150'!D2:D151,"Hard") -> 0 | E21: =SUM(B21:D21) -> 7 | F21: =COUNTIFS('NeetCode 150'!B2:B151,A21,'NeetCode 150'!F2:F151,"Done") -> 0 | G21: =IF(E21=0,0,F21/E21) -> 0
A22: TOTAL | B22: =SUM(B4:B21) -> 28 | C22: =SUM(C4:C21) -> 101 | D22: =SUM(D4:D21) -> 21 | E22: =SUM(E4:E21) -> 150 | F22: =SUM(F4:F21) -> 0 | G22: =IF(E22=0,0,F22/E22) -> 0
